<?xml version="1.0" ?>
<robot name="NICO">

	<link name="base">
		<visual>
			<geometry>
				<mesh filename="meshes/base.stl" scale="0.001 0.001 0.001"/>
			</geometry>
			<origin rpy="0 0 0" xyz="-0.026368 -0.075212 0.525308"/>
			<material name="base_color">
				<color rgba="0.270588 0.270588 0.270588 1"/>
			</material>
		</visual>
		<collision>
			<geometry>
				<mesh filename="meshes/base.stl" scale="0.001 0.001 0.001"/>
			</geometry>
			<origin rpy="0 0 0" xyz="-0.026368 -0.075212 0.525308"/>
		</collision>
		<inertial>
			<mass value="0.607828"/>
			<inertia ixx="0.006338" ixy="0.000004" ixz="0.000248" iyy="0.005208" iyz="0.000001" izz="0.002162"/>
			<origin rpy="0 0 0" xyz="0.01632 -0.000121 0.649656"/>
		</inertial>
	</link>	

	<link name="torso">
		<visual>
			<geometry>
				<mesh filename="meshes/body_plates.stl" scale="0.001 0.001 0.001"/>
			</geometry>
			<origin rpy="0 0 0" xyz="-0.026368 -0.075212 0.525308"/>
			<material name="torso_color">
				<color rgba="0.74902 0.74902 0.74902 1"/>
			</material>
		</visual>
		<collision>
			<geometry>
				<mesh filename="meshes/body_plates.stl" scale="0.001 0.001 0.001"/>
			</geometry>
			<origin rpy="0 0 0" xyz="-0.026368 -0.075212 0.525308"/>
		</collision>
		<inertial>
			<mass value="0.607828"/>
			<inertia ixx="0.006338" ixy="0.000004" ixz="0.000248" iyy="0.005208" iyz="0.000001" izz="0.002162"/>
			<origin rpy="0 0 0" xyz="0.01632 -0.000121 0.649656"/>
		</inertial>
	</link>	


	<joint name="base" type="fixed">
		<parent link="base"/>
		<child link="torso"/>
		<origin rpy="0 0 0" xyz="0.00001 0.00001 0.00001"/>
		<axis xyz="0 0 1"/>
	</joint>

	<link name="r_shoulder">
		<visual>
			<geometry>
				<mesh filename="meshes/right_shoulder.stl" scale="0.001 0.001 0.001"/>
			</geometry>
			<origin rpy="0 0 0" xyz="-0.062271 0.032843 -0.74045"/>
			<material name="r_shoulder_color">
				<color rgba="0.176471 0.176471 0.176471 1"/>
			</material>
		</visual>
		<collision>
			<geometry>
				<mesh filename="meshes/right_shoulder.stl" scale="0.001 0.001 0.001"/>
			</geometry>
			<origin rpy="0 0 0" xyz="-0.062271 0.032843 -0.74045"/>
		</collision>
		<inertial>
			<mass value="0.084038"/>
			<inertia ixx="0.000026" ixy="-0.000001" ixz="-0.000002" iyy="0.000034" iyz="-0" izz="0.000033"/>
			<origin rpy="0 0 0" xyz="0.005637 0.000876 0.033153"/>
		</inertial>
	</link>
	<joint name="r_shoulder" type="revolute">
		<parent link="torso"/>
		<child link="r_shoulder"/>
		<origin rpy="0 0 -0.20444" xyz="0.026783 -0.049912 0.748809"/>
		<axis xyz="0 0 1"/>
		<limit effort="30" lower="-1.745" upper="2.182" velocity="1"/>
	</joint>
	<link name="r_collarbone">
		<visual>
			<geometry>
				<mesh filename="meshes/right_upper_arm.stl" scale="0.001 0.001 0.001"/>
			</geometry>
			<origin rpy="0 0 0" xyz="-0.0285 -0.054827 -0.000102"/>
			<material name="r_collarbone_color">
				<color rgba="0.176471 0.176471 0.176471 1"/>
			</material>
		</visual>
		<collision>
			<geometry>
				<mesh filename="meshes/right_upper_arm.stl" scale="0.001 0.001 0.001"/>
			</geometry>
			<origin rpy="0 0 0" xyz="-0.0285 -0.054827 -0.000102"/>
		</collision>
		<inertial>
			<mass value="0.024811"/>
			<inertia ixx="0.000014" ixy="-0" ixz="0" iyy="0.000011" iyz="-0.000001" izz="0.000019"/>
			<origin rpy="0 0 0" xyz="-0 -0.041345 -0.002364"/>
		</inertial>
	</link>
	<joint name="r_collarbone" type="revolute">
		<parent link="r_shoulder"/>
		<child link="r_collarbone"/>
		<origin rpy="0 0 0.20444" xyz="0.026211 -0.018056 0.037"/>
		<axis xyz="0 -1 0"/>
		<limit effort="30" lower="-3.142" upper="3.124" velocity="1"/>
	</joint>
	<link name="r_upper_arm">
		<visual>
			<geometry>
				<mesh filename="meshes/right_lower_arm.stl" scale="0.001 0.001 0.001"/>
			</geometry>
			<origin rpy="0 0 0" xyz="-0.044001 -0.021 -0.139458"/>
			<material name="r_upper_arm_color">
				<color rgba="0.176471 0.176471 0.176471 1"/>
			</material>
		</visual>
		<collision>
			<geometry>
				<mesh filename="meshes/right_lower_arm.stl" scale="0.001 0.001 0.001"/>
			</geometry>
			<origin rpy="0 0 0" xyz="-0.044001 -0.021 -0.139458"/>
		</collision>
		<inertial>
			<mass value="0.189729"/>
			<inertia ixx="0.000851" ixy="0" ixz="0" iyy="0.000851" iyz="-0.000005" izz="0.000048"/>
			<origin rpy="0 0 0" xyz="-0.02306 -0.000321 -0.0866"/>
		</inertial>
	</link>
	<joint name="r_upper_arm" type="revolute">
		<parent link="r_collarbone"/>
		<child link="r_upper_arm"/>
		<origin rpy="0 0 0" xyz="0.0245 -0.073664 -0.022853"/>
		<axis xyz="1 0 0"/>
		<limit effort="30" lower="-3.002" upper="1.8675" velocity="1"/>
	</joint>
	<link name="r_lower_arm">
		<visual>
			<geometry>
				<mesh filename="meshes/right_wrist_MIR.stl" scale="0.001 0.001 0.001"/>
			</geometry>
			<origin rpy="0 0 0" xyz="0.000017 -0.010775 -0.12546"/>
			<material name="r_lower_arm_color">
				<color rgba="0.176471 0.176471 0.176471 1"/>
			</material>
		</visual>
		<collision>
			<geometry>
				<mesh filename="meshes/right_wrist_MIR.stl" scale="0.001 0.001 0.001"/>
			</geometry>
			<origin rpy="0 0 0" xyz="0.000017 -0.010775 -0.12546"/>
		</collision>
		<inertial>
			<mass value="0.076791"/>
			<inertia ixx="0.000104" ixy="-0" ixz="-0" iyy="0.000095" iyz="-0.000002" izz="0.000021"/>
			<origin rpy="0 0 0" xyz="0 -0.022485 -0.081055"/>
		</inertial>
	</link>
	<joint name="r_elbow" type="revolute">
		<parent link="r_upper_arm"/>
		<child link="r_lower_arm"/>
		<origin rpy="0 0 0" xyz="-0.023001 0.002 -0.1532"/>
		<axis xyz="0 1 0"/>
		<limit effort="30" lower="-1.745" upper="1.745" velocity="1"/>
	</joint>
	<link name="r_wrist">
		<visual>
			<geometry>
				<mesh filename="meshes/right_wrist_iam2.stl" scale="0.001 0.001 0.001"/>
			</geometry>
			<origin rpy="0 0 0" xyz="-0.000319 0.006617 -0.070181"/>
			<material name="r_wrist_color">
				<color rgba="0.74902 0.74902 0.74902 1"/>
			</material>
		</visual>
		<collision>
			<geometry>
				<mesh filename="meshes/right_wrist_iam2.stl" scale="0.001 0.001 0.001"/>
			</geometry>
			<origin rpy="0 0 0" xyz="-0.000319 0.006617 -0.070181"/>
		</collision>
		<inertial>
			<mass value="0.028397"/>
			<inertia ixx="0.000043" ixy="-0" ixz="0.000004" iyy="0.000058" iyz="-0.000007" izz="0.000029"/>
			<origin rpy="0 0 0" xyz="0.000031 -0.011056 -0.0675"/>
		</inertial>
	</link>
	<joint name="r_wrist" type="revolute">
		<parent link="r_lower_arm"/>
		<child link="r_wrist"/>
		<origin rpy="0 0 0.028946" xyz="0 -0.0102 -0.12605"/>
		<axis xyz="0 0 1"/>
		<limit effort="30" lower="-1.571" upper="1.571" velocity="1"/>
	</joint><link name="r_palm">
		<visual>
			<geometry>
				<mesh filename="meshes/right_hand.stl" scale="0.001 0.001 0.001"/>
			</geometry>
			<origin rpy="0 0 0" xyz="-0.022933 0.001906 -0.017233"/>
			<material name="r_palm_color">
				<color rgba="0.74902 0.74902 0.74902 1"/>
			</material>
		</visual>
		<collision>
			<geometry>
				<mesh filename="meshes/right_hand.stl" scale="0.001 0.001 0.001"/>
			</geometry>
			<origin rpy="0 0 0" xyz="-0.022933 0.001906 -0.017233"/>
		</collision>
		<inertial>
			<mass value="0.005332"/>
			<inertia ixx="0.000015" ixy="0.000001" ixz="-0.000004" iyy="0.000017" iyz="0.000004" izz="0.000006"/>
			<origin rpy="0 0 0" xyz="-0.029511 0.002253 -0.023968"/>
		</inertial>
	</link>
	<joint name="r_palm" type="revolute">
		<parent link="r_wrist"/>
		<child link="r_palm"/>
		<origin rpy="-0.433097 0 0" xyz="0.023416 0.006052 -0.070337"/>
		<axis xyz="1 0 0"/>
		<limit effort="30" lower="0" upper="0.872665" velocity="1"/>
	</joint>
	

	<link name="r_finger_segment_1">
		<visual>
			<geometry>
				<mesh filename="meshes/finger_segment.stl" scale="0.001 0.001 0.001"/>
			</geometry>
			<origin rpy="0 0 0" xyz="-0.006681 -0.015507 -0.007416"/>
			<material name="r_finger_segment_1_color">
				<color rgba="0.74902 0.74902 0.74902 1"/>
			</material>
		</visual>
		<collision>
			<geometry>
				<mesh filename="meshes/finger_segment.stl" scale="0.001 0.001 0.001"/>
			</geometry>
			<origin rpy="0 0 0" xyz="-0.006681 -0.015507 -0.007416"/>
		</collision>
		<inertial>
			<mass value="0.000009"/>
			<inertia ixx="0" ixy="0" ixz="-0" iyy="0" iyz="0" izz="0"/>
			<origin rpy="0 0 0" xyz="0.004909 0.000556 -0.005751"/>
		</inertial>
	</link>
	<joint name="r_indexfingers_1" type="revolute">
		<parent link="r_palm"/>
		<child link="r_finger_segment_1"/>
		<origin rpy="-0.578103 0.062904 -3.141593" xyz="-0.001139 0.006226 -0.040004"/>
		<axis xyz="0.998022 0.00962907 0.0621208"/>
		<limit effort="30" lower="-1.309" upper="0" velocity="1"/>
	</joint>
	<link name="r_finger_segment_12">
		<visual>
			<geometry>
				<mesh filename="meshes/finger_segment.stl" scale="0.001 0.001 0.001"/>
			</geometry>
			<origin rpy="0 0 0" xyz="-0.006181 -0.015507 -0.007417"/>
			<material name="r_finger_segment_12_color">
				<color rgba="0.74902 0.74902 0.74902 1"/>
			</material>
		</visual>
		<collision>
			<geometry>
				<mesh filename="meshes/finger_segment.stl" scale="0.001 0.001 0.001"/>
			</geometry>
			<origin rpy="0 0 0" xyz="-0.006181 -0.015507 -0.007417"/>
		</collision>
		<inertial>
			<mass value="0.000009"/>
			<inertia ixx="0" ixy="0" ixz="-0" iyy="0" iyz="0" izz="0"/>
			<origin rpy="0 0 0" xyz="0.005409 0.000556 -0.005751"/>
		</inertial>
	</link>
	<joint name="r_indexfingers_2" type="revolute">
		<parent link="r_finger_segment_1"/>
		<child link="r_finger_segment_12"/>
		<origin rpy="-0.095246 0 0" xyz="-0.0005 0 -0.015999"/>
		<axis xyz="0.998022 0.00962907 0.0621208"/>
		<limit effort="30" lower="-1.309" upper="0" velocity="1"/>
	</joint>
	<link name="r_finger_segment_13">
		<visual>
			<geometry>
				<mesh filename="meshes/fingertip.stl" scale="0.001 0.001 0.001"/>
			</geometry>
			<origin rpy="0 0 0" xyz="0.005514 0.000374 -0.010171"/>
			<material name="r_finger_segment_13_color">
				<color rgba="0.74902 0.74902 0.74902 1"/>
			</material>
		</visual>
		<collision>
			<geometry>
				<mesh filename="meshes/fingertip.stl" scale="0.001 0.001 0.001"/>
			</geometry>
			<origin rpy="0 0 0" xyz="0.005514 0.000374 -0.010171"/>
		</collision>
		<inertial>
			<mass value="0.000008"/>
			<inertia ixx="0" ixy="-0" ixz="-0" iyy="0" iyz="-0" izz="0"/>
			<origin rpy="0 0 0" xyz="0.005013 0.000408 -0.010216"/>
		</inertial>
	</link>
	<joint name="r_indexfingers_3" type="revolute">
		<parent link="r_finger_segment_12"/>
		<child link="r_finger_segment_13"/>
		<origin rpy="-0.109614 0 0" xyz="0 -0 -0.016"/>
		<axis xyz="0.998022 0.00962907 0.0621208"/>
		<limit effort="30" lower="-1.309" upper="0" velocity="1"/>
	</joint>




	
	<link name="r_finger_segment_21">
		<visual>
			<geometry>
				<mesh filename="meshes/finger_segment.stl" scale="0.001 0.001 0.001"/>
			</geometry>
			<origin rpy="0 0 0" xyz="-0.006681 -0.015507 -0.007416"/>
			<material name="r_finger_segment_21_color">
				<color rgba="0.74902 0.74902 0.74902 1"/>
			</material>
		</visual>
		<collision>
			<geometry>
				<mesh filename="meshes/finger_segment.stl" scale="0.001 0.001 0.001"/>
			</geometry>
			<origin rpy="0 0 0" xyz="-0.006681 -0.015507 -0.007416"/>
		</collision>
		<inertial>
			<mass value="0.000009"/>
			<inertia ixx="0" ixy="0" ixz="-0" iyy="0" iyz="0" izz="0"/>
			<origin rpy="0 0 0" xyz="0.004909 0.000556 -0.005751"/>
		</inertial>
	</link>
	<joint name="r_ringfingers_1" type="revolute">
		<parent link="r_palm"/>
		<child link="r_finger_segment_21"/>
		<origin rpy="-0.569851 -0.062904 -3.141593" xyz="-0.035879 0.006226 -0.040569"/>
		<axis xyz="0.998022 -0.00962907 -0.0621208"/>
		<limit effort="30" lower="-1.309" upper="0" velocity="1"/>
	</joint>
	<link name="r_finger_segment_22">
		<visual>
			<geometry>
				<mesh filename="meshes/finger_segment.stl" scale="0.001 0.001 0.001"/>
			</geometry>
			<origin rpy="0 0 0" xyz="-0.006181 -0.015507 -0.007417"/>
			<material name="r_finger_segment_22_color">
				<color rgba="0.74902 0.74902 0.74902 1"/>
			</material>
		</visual>
		<collision>
			<geometry>
				<mesh filename="meshes/finger_segment.stl" scale="0.001 0.001 0.001"/>
			</geometry>
			<origin rpy="0 0 0" xyz="-0.006181 -0.015507 -0.007417"/>
		</collision>
		<inertial>
			<mass value="0.000009"/>
			<inertia ixx="0" ixy="0" ixz="-0" iyy="0" iyz="0" izz="0"/>
			<origin rpy="0 0 0" xyz="0.005409 0.000556 -0.005752"/>
		</inertial>
	</link>
	<joint name="r_ringfingers_2" type="revolute">
		<parent link="r_finger_segment_21"/>
		<child link="r_finger_segment_22"/>
		<origin rpy="-0.095245 0 0" xyz="-0.0005 0 -0.016"/>
		<axis xyz="0.998022 -0.00962907 -0.0621208"/>
		<limit effort="30" lower="-1.309" upper="0" velocity="1"/>
	</joint>
	<link name="r_finger_segment_23">
		<visual>
			<geometry>
				<mesh filename="meshes/fingertip.stl" scale="0.001 0.001 0.001"/>
			</geometry>
			<origin rpy="0 0 0" xyz="0.005514 0.000373 -0.010171"/>
			<material name="r_finger_segment_23_color">
				<color rgba="0.74902 0.74902 0.74902 1"/>
			</material>
		</visual>
		<collision>
			<geometry>
				<mesh filename="meshes/fingertip.stl" scale="0.001 0.001 0.001"/>
			</geometry>
			<origin rpy="0 0 0" xyz="0.005514 0.000373 -0.010171"/>
		</collision>
		<inertial>
			<mass value="0.000008"/>
			<inertia ixx="0" ixy="-0" ixz="-0" iyy="0" iyz="-0" izz="0"/>
			<origin rpy="0 0 0" xyz="0.005013 0.000407 -0.010215"/>
		</inertial>
	</link>
	<joint name="r_ringfingers_3" type="revolute">
		<parent link="r_finger_segment_22"/>
		<child link="r_finger_segment_23"/>
		<origin rpy="-0.109614 0 0" xyz="0 -0 -0.016"/>
		<axis xyz="0.998022 -0.00962907 -0.0621208"/>
		<limit effort="30" lower="-1.309" upper="0" velocity="1"/>
	</joint>



	<link name="r_finger_segment_31">
		<visual>
			<geometry>
				<mesh filename="meshes/finger_segment.stl" scale="0.001 0.001 0.001"/>
			</geometry>
			<origin rpy="0 0 0" xyz="-0.006681 -0.015507 -0.007417"/>
			<material name="r_finger_segment_31_color">
				<color rgba="0.74902 0.74902 0.74902 1"/>
			</material>
		</visual>
		<collision>
			<geometry>
				<mesh filename="meshes/finger_segment.stl" scale="0.001 0.001 0.001"/>
			</geometry>
			<origin rpy="0 0 0" xyz="-0.006681 -0.015507 -0.007417"/>
		</collision>
		<inertial>
			<mass value="0.000009"/>
			<inertia ixx="0" ixy="0" ixz="-0" iyy="0" iyz="0" izz="0"/>
			<origin rpy="0 0 0" xyz="0.004909 0.000556 -0.005752"/>
		</inertial>
	</link>
	<joint name="r_thumb_1" type="revolute">
		<parent link="r_palm"/>
		<child link="r_finger_segment_31"/>
		<origin rpy="1.915504 0 0" xyz="-0.0275 0.0199 -0.00842"/>
		<axis xyz="1 0 0"/>
		<limit effort="30" lower="-1.309" upper="0" velocity="1"/>
	</joint>
	<link name="r_finger_segment_32">
		<visual>
			<geometry>
				<mesh filename="meshes/finger_segment.stl" scale="0.001 0.001 0.001"/>
			</geometry>
			<origin rpy="0 0 0" xyz="-0.006181 -0.015507 -0.007416"/>
			<material name="r_finger_segment_32_color">
				<color rgba="0.74902 0.74902 0.74902 1"/>
			</material>
		</visual>
		<collision>
			<geometry>
				<mesh filename="meshes/finger_segment.stl" scale="0.001 0.001 0.001"/>
			</geometry>
			<origin rpy="0 0 0" xyz="-0.006181 -0.015507 -0.007416"/>
		</collision>
		<inertial>
			<mass value="0.000009"/>
			<inertia ixx="0" ixy="0" ixz="-0" iyy="0" iyz="0" izz="0"/>
			<origin rpy="0 0 0" xyz="0.005409 0.000557 -0.005751"/>
		</inertial>
	</link>
	<joint name="r_thumb_2" type="revolute">
		<parent link="r_finger_segment_31"/>
		<child link="r_finger_segment_32"/>
		<origin rpy="-0.095246 0 0" xyz="-0.0005 -0.000001 -0.016001"/>
		<axis xyz="1 0 0"/>
		<limit effort="30" lower="-1.309" upper="0" velocity="1"/>
	</joint>
	<link name="r_finger_segment_33">
		<visual>
			<geometry>
				<mesh filename="meshes/fingertip.stl" scale="0.001 0.001 0.001"/>
			</geometry>
			<origin rpy="0 0 0" xyz="0.005514 0.000374 -0.010171"/>
			<material name="r_finger_segment_33_color">
				<color rgba="0.74902 0.74902 0.74902 1"/>
			</material>
		</visual>
		<collision>
			<geometry>
				<mesh filename="meshes/fingertip.stl" scale="0.001 0.001 0.001"/>
			</geometry>
			<origin rpy="0 0 0" xyz="0.005514 0.000374 -0.010171"/>
		</collision>
		<inertial>
			<mass value="0.000008"/>
			<inertia ixx="0" ixy="-0" ixz="-0" iyy="0" iyz="-0" izz="0"/>
			<origin rpy="0 0 0" xyz="0.005013 0.000408 -0.010216"/>
		</inertial>
	</link>
	<joint name="r_thumb_3" type="revolute">
		<parent link="r_finger_segment_32"/>
		<child link="r_finger_segment_33"/>
		<origin rpy="-0.109614 0 0" xyz="0 0.000001 -0.015999"/>
		<axis xyz="1 0 0"/>
		<limit effort="30" lower="-1.309" upper="0" velocity="1"/>
	</joint>


	

   <link name="neck">
		<visual>
			<geometry>
				<mesh filename="meshes/neck.stl" scale="0.001 0.001 0.001"/>
			</geometry>
			<origin rpy="0 0 0" xyz="-0.015583 -0.0205 0"/>
			<material name="neck_color">
				<color rgba="0.74902 0.74902 0.74902 1"/>
			</material>
		</visual>
		<collision>
			<geometry>
				<mesh filename="meshes/neck.stl" scale="0.001 0.001 0.001"/>
			</geometry>
			<origin rpy="0 0 0" xyz="-0.015583 -0.0205 0"/>
		</collision>
		<inertial>
			<mass value="0.090439"/>
			<inertia ixx="0.00006" ixy="-0" ixz="-0" iyy="0.000056" iyz="-0.000001" izz="0.000019"/>
			<origin rpy="0 0 0" xyz="0 0.000266 0.050352"/>
		</inertial>
	</link>
	<joint name="neck" type="revolute">
		<parent link="torso"/>
		<child link="neck"/>
		<origin rpy="0 0 0" xyz="0.001283 -0.000212 0.756309"/>
		<axis xyz="0 0 1"/>
		<limit effort="30" lower="-3.124" upper="3.142" velocity="1"/>
	</joint>
	<link name="head">
		<visual>
			<geometry>
				<mesh filename="meshes/head.stl" scale="0.001 0.001 0.001"/>
			</geometry>
			<origin rpy="0 0 0" xyz="-0.003998 -0.016462 0.04478"/>
			<material name="head_color">
				<color rgba="0.74902 0.74902 0.74902 1"/>
			</material>
		</visual>
		<collision>
			<geometry>
				<mesh filename="meshes/head.stl" scale="0.001 0.001 0.001"/>
			</geometry>
			<origin rpy="0 0 0" xyz="-0.003998 -0.016462 0.04478"/>
		</collision>
		<inertial>
			<mass value="0.294137"/>
			<inertia ixx="0.001424" ixy="-0" ixz="0.000083" iyy="0.00159" iyz="-0.000002" izz="0.001485"/>
			<origin rpy="0 0 0" xyz="0.01525 -0.023771 0.09423"/>
		</inertial>
	</link>
	<joint name="head" type="revolute">
		<parent link="neck"/>
		<child link="head"/>
		<origin rpy="0 0 0" xyz="0 0.023001 0.0745"/>
		<axis xyz="0 1 0"/>
		<limit effort="30" lower="-1.553" upper="1.379" velocity="1"/>
	</joint>
	<link name="l_shoulder">
		<visual>
			<geometry>
				<mesh filename="meshes/left_shoulder.stl" scale="0.001 0.001 0.001"/>
			</geometry>
			<origin rpy="0 0 0" xyz="0.014919 0.097299 -0.01461"/>
			<material name="l_shoulder_color">
				<color rgba="0.176471 0.176471 0.176471 1"/>
			</material>
		</visual>
		<collision>
			<geometry>
				<mesh filename="meshes/left_shoulder.stl" scale="0.001 0.001 0.001"/>
			</geometry>
			<origin rpy="0 0 0" xyz="0.014919 0.097299 -0.01461"/>
		</collision>
		<inertial>
			<mass value="0.084038"/>
			<inertia ixx="0.000026" ixy="-0.000001" ixz="-0.000002" iyy="0.000034" iyz="-0" izz="0.000033"/>
			<origin rpy="0 0 0" xyz="0.005702 0.000175 0.033153"/>
		</inertial>
	</link>
	<joint name="l_shoulder" type="revolute">
		<parent link="torso"/>
		<child link="l_shoulder"/>
		<origin rpy="0 0 0.019617" xyz="0.026783 0.049488 0.748809"/>
		<axis xyz="0 0 1"/>
		<limit effort="30" lower="-2.182" upper="1.745" velocity="1"/>
	</joint>
	<link name="l_collarbone">
		<visual>
			<geometry>
				<mesh filename="meshes/left_upper_arm.stl" scale="0.001 0.001 0.001"/>
			</geometry>
			<origin rpy="0 0 0" xyz="-0.00032 -0.000277 0.000298"/>
			<material name="l_collarbone_color">
				<color rgba="0.176471 0.176471 0.176471 1"/>
			</material>
		</visual>
		<collision>
			<geometry>
				<mesh filename="meshes/left_upper_arm.stl" scale="0.001 0.001 0.001"/>
			</geometry>
			<origin rpy="0 0 0" xyz="-0.00032 -0.000277 0.000298"/>
		</collision>
		<inertial>
			<mass value="0.024811"/>
			<inertia ixx="0.000014" ixy="0" ixz="0" iyy="0.000011" iyz="0.000001" izz="0.000019"/>
			<origin rpy="0 0 0" xyz="-0 0.041345 -0.002364"/>
		</inertial>
	</link>
	<joint name="l_collarbone" type="revolute">
		<parent link="l_shoulder"/>
		<child link="l_collarbone"/>
		<origin rpy="0 -0.00445 -0.019538" xyz="0.022445 0.022567 0.037"/>
		<axis xyz="0 1 0"/>
		<limit effort="30" lower="-3.124" upper="3.142" velocity="1"/>
	</joint>
	<link name="l_upper_arm">
		<visual>
			<geometry>
				<mesh filename="meshes/left_lower_arm.stl" scale="0.001 0.001 0.001"/>
			</geometry>
			<origin rpy="0 0 0" xyz="-0.044837 -0.009349 -0.161585"/>
			<material name="l_upper_arm_color">
				<color rgba="0.176471 0.176471 0.176471 1"/>
			</material>
		</visual>
		<collision>
			<geometry>
				<mesh filename="meshes/left_lower_arm.stl" scale="0.001 0.001 0.001"/>
			</geometry>
			<origin rpy="0 0 0" xyz="-0.044837 -0.009349 -0.161585"/>
		</collision>
		<inertial>
			<mass value="0.192388"/>
			<inertia ixx="0.00085" ixy="0" ixz="-0.00005" iyy="0.000853" iyz="0.000001" izz="0.000052"/>
			<origin rpy="0 0 0" xyz="-0.028636 -0.000703 -0.084224"/>
		</inertial>
	</link>
	<joint name="l_upper_arm" type="revolute">
		<parent link="l_collarbone"/>
		<child link="l_upper_arm"/>
		<origin rpy="0.000683 -0.051282 -0.000035" xyz="0.0245 0.073663 -0.022853"/>
		<axis xyz="1 0 0"/>
		<limit effort="30" lower="-1.8675" upper="3.002" velocity="1"/>
	</joint>
	<link name="l_lower_arm">
		<visual>
			<geometry>
				<mesh filename="meshes/left_wrist_MIR.stl" scale="0.001 0.001 0.001"/>
			</geometry>
			<origin rpy="0 0 0" xyz="0.000017 -0.010775 -0.12546"/>
			<material name="l_lower_arm_color">
				<color rgba="0.176471 0.176471 0.176471 1"/>
			</material>
		</visual>
		<collision>
			<geometry>
				<mesh filename="meshes/left_wrist_MIR.stl" scale="0.001 0.001 0.001"/>
			</geometry>
			<origin rpy="0 0 0" xyz="0.000017 -0.010775 -0.12546"/>
		</collision>
		<inertial>
			<mass value="0.076791"/>
			<inertia ixx="0.000104" ixy="-0" ixz="-0" iyy="0.000095" iyz="0.000002" izz="0.000021"/>
			<origin rpy="0 0 0" xyz="0 -0.022485 -0.081055"/>
		</inertial>
	</link>
	<joint name="l_elbow" type="revolute">
		<parent link="l_upper_arm"/>
		<child link="l_lower_arm"/>
		<origin rpy="0 0.055976 0" xyz="-0.035 0.023066 -0.1432"/>
		<axis xyz="0 -1 0"/>
		<limit effort="30" lower="-1.745" upper="1.745" velocity="1"/>
	</joint>

	<link name="l_wrist">
		<visual>
			<geometry>
				<mesh filename="meshes/left_wrist.stl" scale="0.001 0.001 0.001"/>
			</geometry>
			<origin rpy="0 0 0" xyz="-0.000319 0.006617 0.070682"/>
			<material name="l_wrist_color">
				<color rgba="0.74902 0.74902 0.74902 1"/>
			</material>
		</visual>
		<collision>
			<geometry>
				<mesh filename="meshes/left_wrist.stl" scale="0.001 0.001 0.001"/>
			</geometry>
			<origin rpy="0 0 0" xyz="-0.000319 0.006617 0.070682"/>
		</collision>
		<inertial>
			<mass value="0.028361"/>
			<inertia ixx="0.000038" ixy="-0" ixz="-0" iyy="0.000039" iyz="0.000007" izz="0.000015"/>
			<origin rpy="0 0 0" xyz="0.00007 -0.011053 0.067769"/>
		</inertial>
	</link>
	<joint name="l_wrist" type="revolute">
		<parent link="l_lower_arm"/>
		<child link="l_wrist"/>
		<origin rpy="3.141593 0 0.028703" xyz="0 -0.010201 -0.12605"/>
		<axis xyz="0 0 -1"/>
		<limit effort="30" lower="-1.571" upper="1.571" velocity="1"/>
	</joint>
    <link name="l_palm">
		<visual>
			<geometry>
				<mesh filename="meshes/left_hand.stl" scale="0.001 0.001 0.001"/>
			</geometry>
			<origin rpy="0 0 0" xyz="-0.023233 0.001906 0.017234"/>
			<material name="l_palm_color">
				<color rgba="0.74902 0.74902 0.74902 1"/>
			</material>
		</visual>
		<collision>
			<geometry>
				<mesh filename="meshes/left_hand.stl" scale="0.001 0.001 0.001"/>
			</geometry>
			<origin rpy="0 0 0" xyz="-0.023233 0.001906 0.017234"/>
		</collision>
		<inertial>
			<mass value="0.005222"/>
			<inertia ixx="0.000001" ixy="0" ixz="-0" iyy="0.000002" iyz="-0" izz="0.000002"/>
			<origin rpy="0 0 0" xyz="-0.027199 0.000117 0.017191"/>
		</inertial>
	</link>
	<joint name="l_palm" type="revolute">
		<parent link="l_wrist"/>
		<child link="l_palm"/>
		<origin rpy="0.460941 0 0" xyz="0.023416 0.006052 0.070837"/>
		<axis xyz="1 0 0"/>
		<limit effort="30" lower="-0.872665" upper="0" velocity="1"/>
	</joint>





	<link name="l_finger_segment_11">
		<visual>
			<geometry>
				<mesh filename="meshes/finger_segment.stl" scale="0.001 0.001 0.001"/>
			</geometry>
			<origin rpy="0 0 0" xyz="-0.015691 -0.015508 -0.007416"/>
			<material name="l_finger_segment_11_color">
				<color rgba="0.74902 0.74902 0.74902 1"/>
			</material>
		</visual>
		<collision>
			<geometry>
				<mesh filename="meshes/finger_segment.stl" scale="0.001 0.001 0.001"/>
			</geometry>
			<origin rpy="0 0 0" xyz="-0.015691 -0.015508 -0.007416"/>
		</collision>
		<inertial>
			<mass value="0.000009"/>
			<inertia ixx="0" ixy="0" ixz="-0" iyy="0" iyz="0" izz="0"/>
			<origin rpy="0 0 0" xyz="-0.004101 0.000556 -0.005752"/>
		</inertial>
	</link>
	<joint name="l_indexfinger_1" type="revolute">
		<parent link="l_palm"/>
		<child link="l_finger_segment_11"/>
		<origin rpy="-1.130534 0 -3.141593" xyz="-0.028 0.0199 0.00842"/>
		<axis xyz="1 0 0"/>
		<limit effort="30" lower="-1.309" upper="0" velocity="1"/>
	</joint>
	<link name="l_finger_segment_12">
		<visual>
			<geometry>
				<mesh filename="meshes/finger_segment.stl" scale="0.001 0.001 0.001"/>
			</geometry>
			<origin rpy="0 0 0" xyz="-0.006181 -0.015507 -0.007417"/>
			<material name="l_finger_segment_12_color">
				<color rgba="0.74902 0.74902 0.74902 1"/>
			</material>
		</visual>
		<collision>
			<geometry>
				<mesh filename="meshes/finger_segment.stl" scale="0.001 0.001 0.001"/>
			</geometry>
			<origin rpy="0 0 0" xyz="-0.006181 -0.015507 -0.007417"/>
		</collision>
		<inertial>
			<mass value="0.000009"/>
			<inertia ixx="0" ixy="0" ixz="-0" iyy="0" iyz="0" izz="0"/>
			<origin rpy="0 0 0" xyz="0.005409 0.000556 -0.005751"/>
		</inertial>
	</link>
	<joint name="l_indexfinger_2" type="revolute">
		<parent link="l_finger_segment_11"/>
		<child link="l_finger_segment_12"/>
		<origin rpy="-0.095246 0 0" xyz="-0.00951 0 -0.016"/>
		<axis xyz="1 0 0"/>
		<limit effort="30" lower="-1.309" upper="0" velocity="1"/>
	</joint>
	<link name="l_finger_segment_13">
		<visual>
			<geometry>
				<mesh filename="meshes/fingertip.stl" scale="0.001 0.001 0.001"/>
			</geometry>
			<origin rpy="0 0 0" xyz="0.005514 0.000374 -0.010171"/>
			<material name="l_finger_segment_13_color">
				<color rgba="0.74902 0.74902 0.74902 1"/>
			</material>
		</visual>
		<collision>
			<geometry>
				<mesh filename="meshes/fingertip.stl" scale="0.001 0.001 0.001"/>
			</geometry>
			<origin rpy="0 0 0" xyz="0.005514 0.000374 -0.010171"/>
		</collision>
		<inertial>
			<mass value="0.000008"/>
			<inertia ixx="0" ixy="-0" ixz="-0" iyy="0" iyz="-0" izz="0"/>
			<origin rpy="0 0 0" xyz="0.005013 0.000408 -0.010216"/>
		</inertial>
	</link>
	<joint name="l_indexfinger_3" type="revolute">
		<parent link="l_finger_segment_12"/>
		<child link="l_finger_segment_13"/>
		<origin rpy="-0.109614 0 0" xyz="0 -0 -0.016"/>
		<axis xyz="1 0 0"/>
		<limit effort="30" lower="-1.309" upper="0" velocity="1"/>
	</joint>



	<link name="l_finger_segment_21">
		<visual>
			<geometry>
				<mesh filename="meshes/finger_segment.stl" scale="0.001 0.001 0.001"/>
			</geometry>
			<origin rpy="0 0 0" xyz="-0.015691 -0.015506 -0.007417"/>
			<material name="l_finger_segment_21_color">
				<color rgba="0.74902 0.74902 0.74902 1"/>
			</material>
		</visual>
		<collision>
			<geometry>
				<mesh filename="meshes/finger_segment.stl" scale="0.001 0.001 0.001"/>
			</geometry>
			<origin rpy="0 0 0" xyz="-0.015691 -0.015506 -0.007417"/>
		</collision>
		<inertial>
			<mass value="0.000009"/>
			<inertia ixx="0" ixy="0" ixz="-0" iyy="0" iyz="0" izz="0"/>
			<origin rpy="0 0 0" xyz="-0.004101 0.000556 -0.005752"/>
		</inertial>
	</link>
	<joint name="l_ringfinger_1" type="revolute">
		<parent link="l_palm"/>
		<child link="l_finger_segment_21"/>
		<origin rpy="2.492946 0.062904 0" xyz="-0.001439 0.006226 0.040004"/>
		<axis xyz="0.99794 -0.0170003 -0.0618655"/>
		<limit effort="30" lower="-1.309" upper="0" velocity="1"/>
	</joint>
	<link name="l_finger_segment_22">
		<visual>
			<geometry>
				<mesh filename="meshes/finger_segment.stl" scale="0.001 0.001 0.001"/>
			</geometry>
			<origin rpy="0 0 0" xyz="-0.006181 -0.015507 -0.007416"/>
			<material name="l_finger_segment_22_color">
				<color rgba="0.74902 0.74902 0.74902 1"/>
			</material>
		</visual>
		<collision>
			<geometry>
				<mesh filename="meshes/finger_segment.stl" scale="0.001 0.001 0.001"/>
			</geometry>
			<origin rpy="0 0 0" xyz="-0.006181 -0.015507 -0.007416"/>
		</collision>
		<inertial>
			<mass value="0.000009"/>
			<inertia ixx="0" ixy="0" ixz="-0" iyy="0" iyz="0" izz="0"/>
			<origin rpy="0 0 0" xyz="0.005409 0.000556 -0.005751"/>
		</inertial>
	</link>
	<joint name="l_ringfinger_2" type="revolute">
		<parent link="l_finger_segment_21"/>
		<child link="l_finger_segment_22"/>
		<origin rpy="-0.095245 0 0" xyz="-0.00951 0 -0.016"/>
		<axis xyz="0.99794 -0.0170003 -0.0618655"/>
		<limit effort="30" lower="-1.309" upper="0" velocity="1"/>
	</joint>
	<link name="l_finger_segment_23">
		<visual>
			<geometry>
				<mesh filename="meshes/fingertip.stl" scale="0.001 0.001 0.001"/>
			</geometry>
			<origin rpy="0 0 0" xyz="0.005514 0.000374 -0.010171"/>
			<material name="l_finger_segment_23_color">
				<color rgba="0.74902 0.74902 0.74902 1"/>
			</material>
		</visual>
		<collision>
			<geometry>
				<mesh filename="meshes/fingertip.stl" scale="0.001 0.001 0.001"/>
			</geometry>
			<origin rpy="0 0 0" xyz="0.005514 0.000374 -0.010171"/>
		</collision>
		<inertial>
			<mass value="0.000008"/>
			<inertia ixx="0" ixy="-0" ixz="-0" iyy="0" iyz="-0" izz="0"/>
			<origin rpy="0 0 0" xyz="0.005013 0.000408 -0.010216"/>
		</inertial>
	</link>
	<joint name="l_ringfinger_3" type="revolute">
		<parent link="l_finger_segment_22"/>
		<child link="l_finger_segment_23"/>
		<origin rpy="-0.109614 0 0" xyz="0 -0 -0.016"/>
		<axis xyz="0.99794 -0.0170003 -0.0618655"/>
		<limit effort="30" lower="-1.309" upper="0" velocity="1"/>
	</joint>



	<link name="l_finger_segment_31">
		<visual>
			<geometry>
				<mesh filename="meshes/finger_segment.stl" scale="0.001 0.001 0.001"/>
			</geometry>
			<origin rpy="0 0 0" xyz="-0.015691 -0.015507 -0.007416"/>
			<material name="l_finger_segment_31_color">
				<color rgba="0.74902 0.74902 0.74902 1"/>
			</material>
		</visual>
		<collision>
			<geometry>
				<mesh filename="meshes/finger_segment.stl" scale="0.001 0.001 0.001"/>
			</geometry>
			<origin rpy="0 0 0" xyz="-0.015691 -0.015507 -0.007416"/>
		</collision>
		<inertial>
			<mass value="0.000009"/>
			<inertia ixx="0" ixy="0" ixz="-0" iyy="0" iyz="0" izz="0"/>
			<origin rpy="0 0 0" xyz="-0.004101 0.000556 -0.005751"/>
		</inertial>
	</link>
	<joint name="l_thumb_1" type="revolute">
		<parent link="l_palm"/>
		<child link="l_finger_segment_31"/>
		<origin rpy="2.499505 -0.062904 0" xyz="-0.036179 0.006226 0.04057"/>
		<axis xyz="0.998051 0.00234199 0.0623629"/>
		<limit effort="30" lower="-1.309" upper="0" velocity="1"/>
	</joint>
	<link name="l_finger_segment_32">
		<visual>
			<geometry>
				<mesh filename="meshes/finger_segment.stl" scale="0.001 0.001 0.001"/>
			</geometry>
			<origin rpy="0 0 0" xyz="-0.006181 -0.015508 -0.007416"/>
			<material name="l_finger_segment_32_color">
				<color rgba="0.74902 0.74902 0.74902 1"/>
			</material>
		</visual>
		<collision>
			<geometry>
				<mesh filename="meshes/finger_segment.stl" scale="0.001 0.001 0.001"/>
			</geometry>
			<origin rpy="0 0 0" xyz="-0.006181 -0.015508 -0.007416"/>
		</collision>
		<inertial>
			<mass value="0.000009"/>
			<inertia ixx="0" ixy="0" ixz="-0" iyy="0" iyz="0" izz="0"/>
			<origin rpy="0 0 0" xyz="0.005409 0.000556 -0.005751"/>
		</inertial>
	</link>
	<joint name="l_thumb_2" type="revolute">
		<parent link="l_finger_segment_31"/>
		<child link="l_finger_segment_32"/>
		<origin rpy="-0.095246 0 0" xyz="-0.00951 0 -0.016"/>
		<axis xyz="0.998051 0.00234199 0.0623629"/>
		<limit effort="30" lower="-1.309" upper="0" velocity="1"/>
	</joint>
	<link name="l_finger_segment_33">
		<visual>
			<geometry>
				<mesh filename="meshes/fingertip.stl" scale="0.001 0.001 0.001"/>
			</geometry>
			<origin rpy="0 0 0" xyz="0.005514 0.000374 -0.010171"/>
			<material name="l_finger_segment_33_color">
				<color rgba="0.74902 0.74902 0.74902 1"/>
			</material>
		</visual>
		<collision>
			<geometry>
				<mesh filename="meshes/fingertip.stl" scale="0.001 0.001 0.001"/>
			</geometry>
			<origin rpy="0 0 0" xyz="0.005514 0.000374 -0.010171"/>
		</collision>
		<inertial>
			<mass value="0.000008"/>
			<inertia ixx="0" ixy="-0" ixz="-0" iyy="0" iyz="-0" izz="0"/>
			<origin rpy="0 0 0" xyz="0.005013 0.000408 -0.010216"/>
		</inertial>
	</link>
	<joint name="l_thumb_3" type="revolute">
		<parent link="l_finger_segment_32"/>
		<child link="l_finger_segment_33"/>
		<origin rpy="-0.109613 0 0" xyz="-0 -0 -0.015999"/>
		<axis xyz="0.998051 0.00234199 0.0623629"/>
		<limit effort="30" lower="-1.309" upper="0" velocity="1"/>
	</joint>
	
</robot>

